Workbook

Sheet Cleaned Data
K1: Deliverables | AB1: E-Poll Market Research Data - Celebrity Attributes
A2: Celebrity ID | B2: Term (Months) | C2: Net Worth ($M) | D2: Territory | E2: Category | F2: Composite Score | G2: Tier | H2: Estimated Total Cost | I2: Estimated Monthly Cost | J2: Ln(Estimated Monthly Cost) | K2: Super Bowl | L2: Superbowl Cost | M2: Production Days | N2: Cost per Production Day | O2: Social Media Posts | P2: Cost per Post | Q2: Appearances | R2: Cost per Appearance | S2: Tour Sponsorship | T2: Cost per Sponsorship | U2: Live Performances | V2: Cost per Performance | W2: Tickets | X2: Cost per Ticket | Y2: E-Score | Z2: Endorsement Score | AA2: Fan Score | AB2: Social Impact Score | AC2: Total Awareness | AD2: Name Awareness | AE2: Image Awareness | AF2: Like A Lot / Like / Like Somewhat | AG2: Like A Lot / Like | AH2: Like A Lot | AI2: Like | AJ2: Like Somewhat | AK2: Dislike Somewhat | AL2: Dislike | AM2: Dislike A Lot | AN2: Dislike A Lot / Dislike | AO2: Dislike A Lot / Dislike / Dislike Somewhat | AP2: Endorsement: Much more / Somewhat more likely | AQ2: Endorsement: Much more likely | AR2: Endorsement: Somewhat more likely | AS2: Endorsement: No Impact | AT2: Endorsement: Somewhat less likely | AU2: Endorsement: Much less likely | AV2: Endorsement: Somewhat less / Much less likely | AW2: Fan | AX2: Neutral | AY2: Non-fan | AZ2: Total (Followed or Shared) | BA2: Followed | BB2: Shared, Posted or Commented | BC2: Activist | BD2: Aggressive | BE2: Annoying | BF2: Approachable | BG2: Articulate | BH2: Attractive | BI2: Beautiful | BJ2: Boring | BK2: Can Identify With | BL2: Charming | BM2: Classy | BN2: Cold | BO2: Compassionate | BP2: Confident | BQ2: Cool | BR2: Credible | BS2: Cute | BT2: Distinctive Voice | BU2: Dynamic | BV2: Exciting | BW2: Experienced | BX2: Fake | BY2: Funny | BZ2: Glamorous | CA2: Good Energy | CB2: Influential | CC2: Inspirational | CD2: Intelligent | CE2: Interesting | CF2: Over-Exposed | CG2: Physically Fit | CH2: Real (Authentic) | CI2: Sexy | CJ2: Sincere | CK2: Stylish | CL2: Talented | CM2: Trend-Setter | CN2: Trustworthy | CO2: Unique | CP2: Versatile
A3: 363670 | B3: 10 | C3: 40 | D3: United States | E3: Entertainment | F3: =(0.5*AC3)+(0.3*Z3)+(0.2*AA3) -> 51.5 | G3: {=_xlfn.IFS(F3<24.9,"B List",F3<45,"Supporting",F3>=45,"A List")} -> A List | H3: =(K3*L3)+(M3*N3)+(O3*P3)+(Q3*R3)+(S3*T3)+(U3*V3)+(W3*X3) -> 3100000 | I3: =H3/B3 -> 310000 | J3: =LN(I3) -> 12.644328 | K3: 1 | L3: {=_xlfn.IFS(G3="A List",_xlfn.XLOOKUP(E3,$B$39:$F$39,$B$40:$F$40),G3="Supporting",_xlfn.XLOOKUP(E3,$I$39:$M$39,$I$40:$M$40),G3="B List",_xlfn.XLOOKUP(E3,$P$39:$T$39,$P$40:$T$40))} -> 2500000 | M3: 2 | N3: {=_xlfn.IFS(G3="A List",_xlfn.XLOOKUP(E3,$B$39:$F$39,$B$43:$F$43),G3="Supporting",_xlfn.XLOOKUP(E3,$I$39:$M$39,$I$43:$M$43),G3="B List",_xlfn.XLOOKUP(E3,$P$39:$T$39,$P$43:$T$43))} -> 300000 | O3: 0 | P3: {=_xlfn.IFS(G3="A List",_xlfn.XLOOKUP(E3,$B$39:$F$39,$B$45:$F$45),G3="Supporting",_xlfn.XLOOKUP(E3,$I$39:$M$39,$I$45:$M$45),G3="B List",_xlfn.XLOOKUP(E3,$P$39:$T$39,$P$45:$T$45))} -> 70000 | Q3: 0 | R3: {=_xlfn.IFS(G3="A List",_xlfn.XLOOKUP(E3,$B$39:$F$39,$B$44:$F$44),G3="Supporting",_xlfn.XLOOKUP(E3,$I$39:$M$39,$I$44:$M$44),G3="B List",_xlfn.XLOOKUP(E3,$P$39:$T$39,$P$44:$T$44))} -> 150000 | S3: 0 | T3: {=_xlfn.IFS(G3="A List",_xlfn.XLOOKUP(E3,$B$39:$F$39,$B$41:$F$41),G3="Supporting",_xlfn.XLOOKUP(E3,$I$39:$M$39,$I$41:$M$41),G3="B List",_xlfn.XLOOKUP(E3,$P$39:$T$39,$P$41:$T$41))} -> 0 | U3: 0 | V3: {=_xlfn.IFS(G3="A List",_xlfn.XLOOKUP(E3,$B$39:$F$39,$B$42:$F$42),G3="Supporting",_xlfn.XLOOKUP(E3,$I$39:$M$39,$I$42:$M$42),G3="B List",_xlfn.XLOOKUP(E3,$P$39:$T$39,$P$42:$T$42))} -> 0 | W3: 0 | X3: {=_xlfn.IFS(G3="A List",_xlfn.XLOOKUP(E3,$B$39:$F$39,$B$46:$F$46),G3="Supporting",_xlfn.XLOOKUP(E3,$I$39:$M$39,$I$46:$M$46),G3="B List",_xlfn.XLOOKUP(E3,$P$39:$T$39,$P$46:$T$46))} -> 0 | Y3: 99 | Z3: 61 | AA3: 66 | AB3: 47 | AC3: 40 | AD3: 34 | AE3: 46 | AF3: 94 | AG3: 64 | AH3: 31 | AI3: 33 | AJ3: 30 | AK3: 4 | AL3: 1 | AM3: 1 | AN3: 2 | AO3: 6 | AP3: 32 | AQ3: 14 | AR3: 18 | AS3: 66 | AT3: 1 | AU3: 1 | AV3: 2 | AW3: 41 | AX3: 51 | AY3: 8 | AZ3: 21 | BA3: 15 | BB3: 12 | BC3: 3 | BD3: 4 | BE3: 1 | BF3: 11 | BG3: 14 | BH3: 4 | BI3: 2 | BJ3: 2 | BK3: 6 | BL3: 10 | BM3: 15 | BN3: 6 | BO3: 8 | BP3: 24 | BQ3: 22 | BR3: 17 | BS3: 1 | BT3: 30 | BU3: 16 | BV3: 10 | BW3: 35 | BX3: 1 | BY3: 13 | BZ3: 3 | CA3: 19 | CB3: 10 | CC3: 8 | CD3: 18 | CE3: 22 | CF3: 1 | CG3: 5 | CH3: 13 | CI3: 3 | CJ3: 9 | CK3: 9 | CL3: 54 | CM3: 5 | CN3: 8 | CO3: 20 | CP3: 21
A4: 103507 | B4: 24 | C4: 170 | D4: United States | E4: Athlete | F4: =(0.5*AC4)+(0.3*Z4)+(0.2*AA4) -> 50 | G4: {=_xlfn.IFS(F4<24.9,"B List",F4<45,"Supporting",F4>=45,"A List")} -> A List | H4: =(K4*L4)+(M4*N4)+(O4*P4)+(Q4*R4)+(S4*T4)+(U4*V4)+(W4*X4) -> 3575000 | I4: =H4/B4 -> 148958.33 | J4: =LN(I4) -> 11.911422 | K4: 1 | L4: {=_xlfn.IFS(G4="A List",_xlfn.XLOOKUP(E4,$B$39:$F$39,$B$40:$F$40),G4="Supporting",_xlfn.XLOOKUP(E4,$I$39:$M$39,$I$40:$M$40),G4="B List",_xlfn.XLOOKUP(E4,$P$39:$T$39,$P$40:$T$40))} -> 2500000 | M4: 4 | N4: {=_xlfn.IFS(G4="A List",_xlfn.XLOOKUP(E4,$B$39:$F$39,$B$43:$F$43),G4="Supporting",_xlfn.XLOOKUP(E4,$I$39:$M$39,$I$43:$M$43),G4="B List",_xlfn.XLOOKUP(E4,$P$39:$T$39,$P$43:$T$43))} -> 225000 | O4: 0 | P4: {=_xlfn.IFS(G4="A List",_xlfn.XLOOKUP(E4,$B$39:$F$39,$B$45:$F$45),G4="Supporting",_xlfn.XLOOKUP(E4,$I$39:$M$39,$I$45:$M$45),G4="B List",_xlfn.XLOOKUP(E4,$P$39:$T$39,$P$45:$T$45))} -> 75000 | Q4: 1 | R4: {=_xlfn.IFS(G4="A List",_xlfn.XLOOKUP(E4,$B$39:$F$39,$B$44:$F$44),G4="Supporting",_xlfn.XLOOKUP(E4,$I$39:$M$39,$I$44:$M$44),G4="B List",_xlfn.XLOOKUP(E4,$P$39:$T$39,$P$44:$T$44))} -> 175000 | S4: 0 | T4: {=_xlfn.IFS(G4="A List",_xlfn.XLOOKUP(E4,$B$39:$F$39,$B$41:$F$41),G4="Supporting",_xlfn.XLOOKUP(E4,$I$39:$M$39,$I$41:$M$41),G4="B List",_xlfn.XLOOKUP(E4,$P$39:$T$39,$P$41:$T$41))} -> 0 | U4: 0 | V4: {=_xlfn.IFS(G4="A List",_xlfn.XLOOKUP(E4,$B$39:$F$39,$B$42:$F$42),G4="Supporting",_xlfn.XLOOKUP(E4,$I$39:$M$39,$I$42:$M$42),G4="B List",_xlfn.XLOOKUP(E4,$P$39:$T$39,$P$42:$T$42))} -> 0 | W4: 0 | X4: {=_xlfn.IFS(G4="A List",_xlfn.XLOOKUP(E4,$B$39:$F$39,$B$46:$F$46),G4="Supporting",_xlfn.XLOOKUP(E4,$I$39:$M$39,$I$46:$M$46),G4="B List",_xlfn.XLOOKUP(E4,$P$39:$T$39,$P$46:$T$46))} -> 400 | Y4: 98 | Z4: 57 | AA4: 62 | AB4: 40 | AC4: 41 | AD4: 52 | AE4: 31 | AF4: 91 | AG4: 60 | AH4: 23 | AI4: 37 | AJ4: 31 | AK4: 6 | AL4: 2 | AM4: 1 | AN4: 3 | AO4: 9 | AP4: 20 | AQ4: 9 | AR4: 11 | AS4: 75 | AT4: 2 | AU4: 3 | AV4: 5 | AW4: 38 | AX4: 53 | AY4: 9 | AZ4: 15 | BA4: 12 | BB4: 7 | BC4: 5 | BD4: 1 | BE4: 3 | BF4: 12 | BG4: 12 | BH4: 15 | BI4: 3 | BJ4: 3 | BK4: 4 | BL4: 17 | BM4: 12 | BN4: 1 | BO4: 8 | BP4: 30 | BQ4: 18 | BR4: 14 | BS4: 8 | BT4: 14 | BU4: 13 | BV4: 11 | BW4: 32 | BX4: 2 | BY4: 13 | BZ4: 5 | CA4: 24 | CB4: 18 | CC4: 8 | CD4: 22 | CE4: 19 | CF4: 4 | CG4: 17 | CH4: 14 | CI4: 7 | CJ4: 11 | CK4: 8 | CL4: 50 | CM4: 4 | CN4: 8 | CO4: 9 | CP4: 15
A5: 554026 | B5: 18 | C5: 50 | D5: United States | E5: Music Artist | F5: =(0.5*AC5)+(0.3*Z5)+(0.2*AA5) -> 49.7 | G5: {=_xlfn.IFS(F5<24.9,"B List",F5<45,"Supporting",F5>=45,"A List")} -> A List | H5: =(K5*L5)+(M5*N5)+(O5*P5)+(Q5*R5)+(S5*T5)+(U5*V5)+(W5*X5) -> 8185000 | I5: =H5/B5 -> 454722.22 | J5: =LN(I5) -> 13.027442 | K5: 1 | L5: {=_xlfn.IFS(G5="A List",_xlfn.XLOOKUP(E5,$B$39:$F$39,$B$40:$F$40),G5="Supporting",_xlfn.XLOOKUP(E5,$I$39:$M$39,$I$40:$M$40),G5="B List",_xlfn.XLOOKUP(E5,$P$39:$T$39,$P$40:$T$40))} -> 2500000 | M5: 3 | N5: {=_xlfn.IFS(G5="A List",_xlfn.XLOOKUP(E5,$B$39:$F$39,$B$43:$F$43),G5="Supporting",_xlfn.XLOOKUP(E5,$I$39:$M$39,$I$43:$M$43),G5="B List",_xlfn.XLOOKUP(E5,$P$39:$T$39,$P$43:$T$43))} -> 250000 | O5: 15 | P5: {=_xlfn.IFS(G5="A List",_xlfn.XLOOKUP(E5,$B$39:$F$39,$B$45:$F$45),G5="Supporting",_xlfn.XLOOKUP(E5,$I$39:$M$39,$I$45:$M$45),G5="B List",_xlfn.XLOOKUP(E5,$P$39:$T$39,$P$45:$T$45))} -> 80000 | Q5: 1 | R5: {=_xlfn.IFS(G5="A List",_xlfn.XLOOKUP(E5,$B$39:$F$39,$B$44:$F$44),G5="Supporting",_xlfn.XLOOKUP(E5,$I$39:$M$39,$I$44:$M$44),G5="B List",_xlfn.XLOOKUP(E5,$P$39:$T$39,$P$44:$T$44))} -> 175000 | S5: 1 | T5: {=_xlfn.IFS(G5="A List",_xlfn.XLOOKUP(E5,$B$39:$F$39,$B$41:$F$41),G5="Supporting",_xlfn.XLOOKUP(E5,$I$39:$M$39,$I$41:$M$41),G5="B List",_xlfn.XLOOKUP(E5,$P$39:$T$39,$P$41:$T$41))} -> 1500000 | U5: 2 | V5: {=_xlfn.IFS(G5="A List",_xlfn.XLOOKUP(E5,$B$39:$F$39,$B$42:$F$42),G5="Supporting",_xlfn.XLOOKUP(E5,$I$39:$M$39,$I$42:$M$42),G5="B List",_xlfn.XLOOKUP(E5,$P$39:$T$39,$P$42:$T$42))} -> 1000000 | W5: 200 | X5: {=_xlfn.IFS(G5="A List",_xlfn.XLOOKUP(E5,$B$39:$F$39,$B$46:$F$46),G5="Supporting",_xlfn.XLOOKUP(E5,$I$39:$M$39,$I$46:$M$46),G5="B List",_xlfn.XLOOKUP(E5,$P$39:$T$39,$P$46:$T$46))} -> 300 | Y5: 96 | Z5: 59 | AA5: 50 | AB5: 59 | AC5: 44 | AD5: 49 | AE5: 38 | AF5: 81 | AG5: 49 | AH5: 23 | AI5: 25 | AJ5: 33 | AK5: 11 | AL5: 5 | AM5: 3 | AN5: 8 | AO5: 19 | AP5: 33 | AQ5: 14 | AR5: 19 | AS5: 54 | AT5: 7 | AU5: 6 | AV5: 13 | AW5: 28 | AX5: 49 | AY5: 23 | AZ5: 30 | BA5: 22 | BB5: 15 | BC5: 3 | BD5: 4 | BE5: 7 | BF5: 11 | BG5: 6 | BH5: 5 | BI5: 3 | BJ5: 4 | BK5: 5 | BL5: 9 | BM5: 5 | BN5: 2 | BO5: 10 | BP5: 22 | BQ5: 28 | BR5: 7 | BS5: 3 | BT5: 27 | BU5: 10 | BV5: 12 | BW5: 14 | BX5: 4 | BY5: 15 | BZ5: 3 | CA5: 28 | CB5: 17 | CC5: 11 | CD5: 9 | CE5: 20 | CF5: 8 | CG5: 2 | CH5: 14 | CI5: 3 | CJ5: 8 | CK5: 10 | CL5: 38 | CM5: 11 | CN5: 5 | CO5: 24 | CP5: 11
A6: 124932 | B6: 12 | C6: 100 | D6: United States | E6: Entertainment | F6: =(0.5*AC6)+(0.3*Z6)+(0.2*AA6) -> 49.6 | G6: {=_xlfn.IFS(F6<24.9,"B List",F6<45,"Supporting",F6>=45,"A List")} -> A List | H6: =(K6*L6)+(M6*N6)+(O6*P6)+(Q6*R6)+(S6*T6)+(U6*V6)+(W6*X6) -> 3240000 | I6: =H6/B6 -> 270000 | J6: =LN(I6) -> 12.506177 | K6: 1 | L6: {=_xlfn.IFS(G6="A List",_xlfn.XLOOKUP(E6,$B$39:$F$39,$B$40:$F$40),G6="Supporting",_xlfn.XLOOKUP(E6,$I$39:$M$39,$I$40:$M$40),G6="B List",_xlfn.XLOOKUP(E6,$P$39:$T$39,$P$40:$T$40))} -> 2500000 | M6: 2 | N6: {=_xlfn.IFS(G6="A List",_xlfn.XLOOKUP(E6,$B$39:$F$39,$B$43:$F$43),G6="Supporting",_xlfn.XLOOKUP(E6,$I$39:$M$39,$I$43:$M$43),G6="B List",_xlfn.XLOOKUP(E6,$P$39:$T$39,$P$43:$T$43))} -> 300000 | O6: 2 | P6: {=_xlfn.IFS(G6="A List",_xlfn.XLOOKUP(E6,$B$39:$F$39,$B$45:$F$45),G6="Supporting",_xlfn.XLOOKUP(E6,$I$39:$M$39,$I$45:$M$45),G6="B List",_xlfn.XLOOKUP(E6,$P$39:$T$39,$P$45:$T$45))} -> 70000 | Q6: 0 | R6: {=_xlfn.IFS(G6="A List",_xlfn.XLOOKUP(E6,$B$39:$F$39,$B$44:$F$44),G6="Supporting",_xlfn.XLOOKUP(E6,$I$39:$M$39,$I$44:$M$44),G6="B List",_xlfn.XLOOKUP(E6,$P$39:$T$39,$P$44:$T$44))} -> 150000 | S6: 0 | T6: {=_xlfn.IFS(G6="A List",_xlfn.XLOOKUP(E6,$B$39:$F$39,$B$41:$F$41),G6="Supporting",_xlfn.XLOOKUP(E6,$I$39:$M$39,$I$41:$M$41),G6="B List",_xlfn.XLOOKUP(E6,$P$39:$T$39,$P$41:$T$41))} -> 0 | U6: 0 | V6: {=_xlfn.IFS(G6="A List",_xlfn.XLOOKUP(E6,$B$39:$F$39,$B$42:$F$42),G6="Supporting",_xlfn.XLOOKUP(E6,$I$39:$M$39,$I$42:$M$42),G6="B List",_xlfn.XLOOKUP(E6,$P$39:$T$39,$P$42:$T$42))} -> 0 | W6: 0 | X6: {=_xlfn.IFS(G6="A List",_xlfn.XLOOKUP(E6,$B$39:$F$39,$B$46:$F$46),G6="Supporting",_xlfn.XLOOKUP(E6,$I$39:$M$39,$I$46:$M$46),G6="B List",_xlfn.XLOOKUP(E6,$P$39:$T$39,$P$46:$T$46))} -> 0 | Y6: 99 | Z6: 58 | AA6: 61 | AB6: 38 | AC6: 40 | AD6: 44 | AE6: 36 | AF6: 95 | AG6: 67 | AH6: 23 | AI6: 44 | AJ6: 27 | AK6: 4 | AL6: 1 | AM6: 1 | AN6: 1 | AO6: 5 | AP6: 24 | AQ6: 9 | AR6: 15 | AS6: 75 | AT6: 1 | AU6: 1 | AV6: 2 | AW6: 37 | AX6: 57 | AY6: 6 | AZ6: 15 | BA6: 10 | BB6: 7 | BC6: 1 | BD6: 1 | BE6: 1 | BF6: 13 | BG6: 10 | BH6: 14 | BI6: 1 | BJ6: 1 | BK6: 5 | BL6: 18 | BM6: 16 | BN6: 2 | BO6: 4 | BP6: 28 | BQ6: 23 | BR6: 14 | BS6: 5 | BT6: 18 | BU6: 11 | BV6: 11 | BW6: 38 | BX6: 2 | BY6: 16 | BZ6: 4 | CA6: 24 | CB6: 11 | CC6: 7 | CD6: 13 | CE6: 20 | CF6: 2 | CG6: 6 | CH6: 17 | CI6: 8 | CJ6: 10 | CK6: 7 | CL6: 49 | CM6: 5 | CN6: 10 | CO6: 11 | CP6: 16
A7: 245103 | B7: 36 | C7: 250 | D7: United States | E7: Athlete | F7: =(0.5*AC7)+(0.3*Z7)+(0.2*AA7) -> 49.6 | G7: {=_xlfn.IFS(F7<24.9,"B List",F7<45,"Supporting",F7>=45,"A List")} -> A List | H7: =(K7*L7)+(M7*N7)+(O7*P7)+(Q7*R7)+(S7*T7)+(U7*V7)+(W7*X7) -> 3650000 | I7: =H7/B7 -> 101388.89 | J7: =LN(I7) -> 11.526719 | K7: 1 | L7: {=_xlfn.IFS(G7="A List",_xlfn.XLOOKUP(E7,$B$39:$F$39,$B$40:$F$40),G7="Supporting",_xlfn.XLOOKUP(E7,$I$39:$M$39,$I$40:$M$40),G7="B List",_xlfn.XLOOKUP(E7,$P$39:$T$39,$P$40:$T$40))} -> 2500000 | M7: 2 | N7: {=_xlfn.IFS(G7="A List",_xlfn.XLOOKUP(E7,$B$39:$F$39,$B$43:$F$43),G7="Supporting",_xlfn.XLOOKUP(E7,$I$39:$M$39,$I$43:$M$43),G7="B List",_xlfn.XLOOKUP(E7,$P$39:$T$39,$P$43:$T$43))} -> 225000 | O7: 0 | P7: {=_xlfn.IFS(G7="A List",_xlfn.XLOOKUP(E7,$B$39:$F$39,$B$45:$F$45),G7="Supporting",_xlfn.XLOOKUP(E7,$I$39:$M$39,$I$45:$M$45),G7="B List",_xlfn.XLOOKUP(E7,$P$39:$T$39,$P$45:$T$45))} -> 75000 | Q7: 4 | R7: {=_xlfn.IFS(G7="A List",_xlfn.XLOOKUP(E7,$B$39:$F$39,$B$44:$F$44),G7="Supporting",_xlfn.XLOOKUP(E7,$I$39:$M$39,$I$44:$M$44),G7="B List",_xlfn.XLOOKUP(E7,$P$39:$T$39,$P$44:$T$44))} -> 175000 | S7: 0 | T7: {=_xlfn.IFS(G7="A List",_xlfn.XLOOKUP(E7,$B$39:$F$39,$B$41:$F$41),G7="Supporting",_xlfn.XLOOKUP(E7,$I$39:$M$39,$I$41:$M$41),G7="B List",_xlfn.XLOOKUP(E7,$P$39:$T$39,$P$41:$T$41))} -> 0 | U7: 0 | V7: {=_xlfn.IFS(G7="A List",_xlfn.XLOOKUP(E7,$B$39:$F$39,$B$42:$F$42),G7="Supporting",_xlfn.XLOOKUP(E7,$I$39:$M$39,$I$42:$M$42),G7="B List",_xlfn.XLOOKUP(E7,$P$39:$T$39,$P$42:$T$42))} -> 0 | W7: 0 | X7: {=_xlfn.IFS(G7="A List",_xlfn.XLOOKUP(E7,$B$39:$F$39,$B$46:$F$46),G7="Supporting",_xlfn.XLOOKUP(E7,$I$39:$M$39,$I$46:$M$46),G7="B List",_xlfn.XLOOKUP(E7,$P$39:$T$39,$P$46:$T$46))} -> 400 | Y7: 98 | Z7: 58 | AA7: 51 | AB7: 47 | AC7: 44 | AD7: 49 | AE7: 40 | AF7: 86 | AG7: 51 | AH7: 19 | AI7: 32 | AJ7: 35 | AK7: 9 | AL7: 2 | AM7: 2 | AN7: 4 | AO7: 14 | AP7: 24 | AQ7: 10 | AR7: 15 | AS7: 69 | AT7: 3 | AU7: 3 | AV7: 6 | AW7: 29 | AX7: 56 | AY7: 15 | AZ7: 18 | BA7: 11 | BB7: 10 | BC7: 2 | BD7: 2 | BE7: 5 | BF7: 11 | BG7: 7 | BH7: 4 | BI7: 2 | BJ7: 4 | BK7: 5 | BL7: 9 | BM7: 9 | BN7: 1 | BO7: 7 | BP7: 28 | BQ7: 16 | BR7: 15 | BS7: 2 | BT7: 19 | BU7: 9 | BV7: 11 | BW7: 30 | BX7: 4 | BY7: 21 | BZ7: 2 | CA7: 23 | CB7: 18 | CC7: 12 | CD7: 16 | CE7: 12 | CF7: 10 | CG7: 30 | CH7: 15 | CI7: 2 | CJ7: 9 | CK7: 3 | CL7: 39 | CM7: 6 | CN7: 9 | CO7: 9 | CP7: 7
A8: 697021 | B8: 11 | C8: 30 | D8: United States | E8: Music Artist | F8: =(0.5*AC8)+(0.3*Z8)+(0.2*AA8) -> 45.2 | G8: {=_xlfn.IFS(F8<24.9,"B List",F8<45,"Supporting",F8>=45,"A List")} -> A List | H8: =(K8*L8)+(M8*N8)+(O8*P8)+(Q8*R8)+(S8*T8)+(U8*V8)+(W8*X8) -> 1255000 | I8: =H8/B8 -> 114090.91 | J8: =LN(I8) -> 11.644751 | K8: 0 | L8: {=_xlfn.IFS(G8="A List",_xlfn.XLOOKUP(E8,$B$39:$F$39,$B$40:$F$40),G8="Supporting",_xlfn.XLOOKUP(E8,$I$39:$M$39,$I$40:$M$40),G8="B List",_xlfn.XLOOKUP(E8,$P$39:$T$39,$P$40:$T$40))} -> 2500000 | M8: 1 | N8: {=_xlfn.IFS(G8="A List",_xlfn.XLOOKUP(E8,$B$39:$F$39,$B$43:$F$43),G8="Supporting",_xlfn.XLOOKUP(E8,$I$39:$M$39,$I$43:$M$43),G8="B List",_xlfn.XLOOKUP(E8,$P$39:$T$39,$P$43:$T$43))} -> 250000 | O8: 6 | P8: {=_xlfn.IFS(G8="A List",_xlfn.XLOOKUP(E8,$B$39:$F$39,$B$45:$F$45),G8="Supporting",_xlfn.XLOOKUP(E8,$I$39:$M$39,$I$45:$M$45),G8="B List",_xlfn.XLOOKUP(E8,$P$39:$T$39,$P$45:$T$45))} -> 80000 | Q8: 3 | R8: {=_xlfn.IFS(G8="A List",_xlfn.XLOOKUP(E8,$B$39:$F$39,$B$44:$F$44),G8="Supporting",_xlfn.XLOOKUP(E8,$I$39:$M$39,$I$44:$M$44),G8="B List",_xlfn.XLOOKUP(E8,$P$39:$T$39,$P$44:$T$44))} -> 175000 | S8: 0 | T8: {=_xlfn.IFS(G8="A List",_xlfn.XLOOKUP(E8,$B$39:$F$39,$B$41:$F$41),G8="Supporting",_xlfn.XLOOKUP(E8,$I$39:$M$39,$I$41:$M$41),G8="B List",_xlfn.XLOOKUP(E8,$P$39:$T$39,$P$41:$T$41))} -> 1500000 | U8: 0 | V8: {=_xlfn.IFS(G8="A List",_xlfn.XLOOKUP(E8,$B$39:$F$39,$B$42:$F$42),G8="Supporting",_xlfn.XLOOKUP(E8,$I$39:$M$39,$I$42:$M$42),G8="B List",_xlfn.XLOOKUP(E8,$P$39:$T$39,$P$42:$T$42))} -> 1000000 | W8: 0 | X8: {=_xlfn.IFS(G8="A List",_xlfn.XLOOKUP(E8,$B$39:$F$39,$B$46:$F$46),G8="Supporting",_xlfn.XLOOKUP(E8,$I$39:$M$39,$I$46:$M$46),G8="B List",_xlfn.XLOOKUP(E8,$P$39:$T$39,$P$46:$T$46))} -> 300 | Y8: 95 | Z8: 55 | AA8: 56 | AB8: 55 | AC8: 35 | AD8: 39 | AE8: 32 | AF8: 83 | AG8: 51 | AH8: 22 | AI8: 29 | AJ8: 32 | AK8: 11 | AL8: 3 | AM8: 2 | AN8: 6 | AO8: 17 | AP8: 31 | AQ8: 15 | AR8: 15 | AS8: 63 | AT8: 4 | AU8: 3 | AV8: 7 | AW8: 34 | AX8: 50 | AY8: 17 | AZ8: 28 | BA8: 21 | BB8: 13 | BC8: 4 | BD8: 3 | BE8: 4 | BF8: 10 | BG8: 8 | BH8: 7 | BI8: 2 | BJ8: 2 | BK8: 5 | BL8: 10 | BM8: 6 | BN8: 3 | BO8: 4 | BP8: 22 | BQ8: 26 | BR8: 8 | BS8: 5 | BT8: 26 | BU8: 14 | BV8: 13 | BW8: 22 | BX8: 3 | BY8: 21 | BZ8: 6 | CA8: 25 | CB8: 14 | CC8: 9 | CD8: 13 | CE8: 13 | CF8: 4 | CG8: 7 | CH8: 11 | CI8: 4 | CJ8: 8 | CK8: 16 | CL8: 36 | CM8: 11 | CN8: 7 | CO8: 16 | CP8: 10
A9: 159642 | B9: 12 | C9: 100 | D9: United States | E9: Athlete | F9: =(0.5*AC9)+(0.3*Z9)+(0.2*AA9) -> 44.7 | G9: {=_xlfn.IFS(F9<24.9,"B List",F9<45,"Supporting",F9>=45,"A List")} -> Supporting | H9: =(K9*L9)+(M9*N9)+(O9*P9)+(Q9*R9)+(S9*T9)+(U9*V9)+(W9*X9) -> 370000 | I9: =H9/B9 -> 30833.333 | J9: =LN(I9) -> 10.336352 | K9: 0 | L9: {=_xlfn.IFS(G9="A List",_xlfn.XLOOKUP(E9,$B$39:$F$39,$B$40:$F$40),G9="Supporting",_xlfn.XLOOKUP(E9,$I$39:$M$39,$I$40:$M$40),G9="B List",_xlfn.XLOOKUP(E9,$P$39:$T$39,$P$40:$T$40))} -> 1000000 | M9: 1 | N9: {=_xlfn.IFS(G9="A List",_xlfn.XLOOKUP(E9,$B$39:$F$39,$B$43:$F$43),G9="Supporting",_xlfn.XLOOKUP(E9,$I$39:$M$39,$I$43:$M$43),G9="B List",_xlfn.XLOOKUP(E9,$P$39:$T$39,$P$43:$T$43))} -> 85000 | O9: 5 | P9: {=_xlfn.IFS(G9="A List",_xlfn.XLOOKUP(E9,$B$39:$F$39,$B$45:$F$45),G9="Supporting",_xlfn.XLOOKUP(E9,$I$39:$M$39,$I$45:$M$45),G9="B List",_xlfn.XLOOKUP(E9,$P$39:$T$39,$P$45:$T$45))} -> 35000 | Q9: 2 | R9: {=_xlfn.IFS(G9="A List",_xlfn.XLOOKUP(E9,$B$39:$F$39,$B$44:$F$44),G9="Supporting",_xlfn.XLOOKUP(E9,$I$39:$M$39,$I$44:$M$44),G9="B List",_xlfn.XLOOKUP(E9,$P$39:$T$39,$P$44:$T$44))} -> 55000 | S9: 0 | T9: {=_xlfn.IFS(G9="A List",_xlfn.XLOOKUP(E9,$B$39:$F$39,$B$41:$F$41),G9="Supporting",_xlfn.XLOOKUP(E9,$I$39:$M$39,$I$41:$M$41),G9="B List",_xlfn.XLOOKUP(E9,$P$39:$T$39,$P$41:$T$41))} -> 0 | U9: 0 | V9: {=_xlfn.IFS(G9="A List",_xlfn.XLOOKUP(E9,$B$39:$F$39,$B$42:$F$42),G9="Supporting",_xlfn.XLOOKUP(E9,$I$39:$M$39,$I$42:$M$42),G9="B List",_xlfn.XLOOKUP(E9,$P$39:$T$39,$P$42:$T$42))} -> 0 | W9: 0 | X9: {=_xlfn.IFS(G9="A List",_xlfn.XLOOKUP(E9,$B$39:$F$39,$B$46:$F$46),G9="Supporting",_xlfn.XLOOKUP(E9,$I$39:$M$39,$I$46:$M$46),G9="B List",_xlfn.XLOOKUP(E9,$P$39:$T$39,$P$46:$T$46))} -> 150 | Y9: 85 | Z9: 47 | AA9: 43 | AB9: 48 | AC9: 44 | AD9: 46 | AE9: 42 | AF9: 66 | AG9: 37 | AH9: 14 | AI9: 23 | AJ9: 29 | AK9: 17 | AL9: 7 | AM9: 10 | AN9: 18 | AO9: 34 | AP9: 20 | AQ9: 9 | AR9: 11 | AS9: 61 | AT9: 8 | AU9: 11 | AV9: 19 | AW9: 23 | AX9: 44 | AY9: 33 | AZ9: 17 | BA9: 11 | BB9: 8 | BC9: 1 | BD9: 5 | BE9: 17 | BF9: 7 | BG9: 5 | BH9: 6 | BI9: 2 | BJ9: 6 | BK9: 4 | BL9: 7 | BM9: 8 | BN9: 3 | BO9: 8 | BP9: 28 | BQ9: 17 | BR9: 10 | BS9: 4 | BT9: 17 | BU9: 11 | BV9: 12 | BW9: 25 | BX9: 9 | BY9: 6 | BZ9: 2 | CA9: 22 | CB9: 16 | CC9: 10 | CD9: 11 | CE9: 12 | CF9: 21 | CG9: 38 | CH9: 10 | CI9: 4 | CJ9: 6 | CK9: 5 | CL9: 47 | CM9: 7 | CN9: 5 | CO9: 10 | CP9: 8
A10: 965832 | B10: 9 | C10: 40 | D10: United States | E10: Entertainment | F10: =(0.5*AC10)+(0.3*Z10)+(0.2*AA10) -> 41.1 | G10: {=_xlfn.IFS(F10<24.9,"B List",F10<45,"Supporting",F10>=45,"A List")} -> Supporting | H10: =(K10*L10)+(M10*N10)+(O10*P10)+(Q10*R10)+(S10*T10)+(U10*V10)+(W10*X10) -> 355000 | I10: =H10/B10 -> 39444.444 | J10: =LN(I10) -> 10.582648 | K10: 0 | L10: {=_xlfn.IFS(G10="A List",_xlfn.XLOOKUP(E10,$B$39:$F$39,$B$40:$F$40),G10="Supporting",_xlfn.XLOOKUP(E10,$I$39:$M$39,$I$40:$M$40),G10="B List",_xlfn.XLOOKUP(E10,$P$39:$T$39,$P$40:$T$40))} -> 1000000 | M10: 2 | N10: {=_xlfn.IFS(G10="A List",_xlfn.XLOOKUP(E10,$B$39:$F$39,$B$43:$F$43),G10="Supporting",_xlfn.XLOOKUP(E10,$I$39:$M$39,$I$43:$M$43),G10="B List",_xlfn.XLOOKUP(E10,$P$39:$T$39,$P$43:$T$43))} -> 125000 | O10: 3 | P10: {=_xlfn.IFS(G10="A List",_xlfn.XLOOKUP(E10,$B$39:$F$39,$B$45:$F$45),G10="Supporting",_xlfn.XLOOKUP(E10,$I$39:$M$39,$I$45:$M$45),G10="B List",_xlfn.XLOOKUP(E10,$P$39:$T$39,$P$45:$T$45))} -> 35000 | Q10: 0 | R10: {=_xlfn.IFS(G10="A List",_xlfn.XLOOKUP(E10,$B$39:$F$39,$B$44:$F$44),G10="Supporting",_xlfn.XLOOKUP(E10,$I$39:$M$39,$I$44:$M$44),G10="B List",_xlfn.XLOOKUP(E10,$P$39:$T$39,$P$44:$T$44))} -> 50000 | S10: 0 | T10: {=_xlfn.IFS(G10="A List",_xlfn.XLOOKUP(E10,$B$39:$F$39,$B$41:$F$41),G10="Supporting",_xlfn.XLOOKUP(E10,$I$39:$M$39,$I$41:$M$41),G10="B List",_xlfn.XLOOKUP(E10,$P$39:$T$39,$P$41:$T$41))} -> 0 | U10: 0 | V10: {=_xlfn.IFS(G10="A List",_xlfn.XLOOKUP(E10,$B$39:$F$39,$B$42:$F$42),G10="Supporting",_xlfn.XLOOKUP(E10,$I$39:$M$39,$I$42:$M$42),G10="B List",_xlfn.XLOOKUP(E10,$P$39:$T$39,$P$42:$T$42))} -> 0 | W10: 0 | X10: {=_xlfn.IFS(G10="A List",_xlfn.XLOOKUP(E10,$B$39:$F$39,$B$46:$F$46),G10="Supporting",_xlfn.XLOOKUP(E10,$I$39:$M$39,$I$46:$M$46),G10="B List",_xlfn.XLOOKUP(E10,$P$39:$T$39,$P$46:$T$46))} -> 0 | Y10: 88 | Z10: 49 | AA10: 47 | AB10: 50 | AC10: 34 | AD10: 36 | AE10: 32 | AF10: 73 | AG10: 46 | AH10: 22 | AI10: 24 | AJ10: 27 | AK10: 13 | AL10: 7 | AM10: 8 | AN10: 15 | AO10: 27 | AP10: 31 | AQ10: 15 | AR10: 16 | AS10: 50 | AT10: 8 | AU10: 11 | AV10: 19 | AW10: 29 | AX10: 42 | AY10: 28 | AZ10: 25 | BA10: 18 | BB10: 14 | BC10: 3 | BD10: 2 | BE10: 15 | BF10: 6 | BG10: 6 | BH10: 39 | BI10: 35 | BJ10: 9 | BK10: 2 | BL10: 13 | BM10: 11 | BN10: 5 | BO10: 6 | BP10: 26 | BQ10: 12 | BR10: 6 | BS10: 24 | BT10: 12 | BU10: 7 | BV10: 10 | BW10: 7 | BX10: 14 | BY10: 10 | BZ10: 20 | CA10: 18 | CB10: 15 | CC10: 8 | CD10: 10 | CE10: 13 | CF10: 19 | CG10: 19 | CH10: 6 | CI10: 35 | CJ10: 4 | CK10: 17 | CL10: 18 | CM10: 11 | CN10: 6 | CO10: 7 | CP10: 6
A11: 741355 | B11: 24 | C11: 450 | D11: Global | E11: Athlete | F11: =(0.5*AC11)+(0.3*Z11)+(0.2*AA11) -> 40.7 | G11: {=_xlfn.IFS(F11<24.9,"B List",F11<45,"Supporting",F11>=45,"A List")} -> Supporting | H11: =(K11*L11)+(M11*N11)+(O11*P11)+(Q11*R11)+(S11*T11)+(U11*V11)+(W11*X11) -> 1685000 | I11: =H11/B11 -> 70208.333 | J11: =LN(I11) -> 11.159222 | K11: 1 | L11: {=_xlfn.IFS(G11="A List",_xlfn.XLOOKUP(E11,$B$39:$F$39,$B$40:$F$40),G11="Supporting",_xlfn.XLOOKUP(E11,$I$39:$M$39,$I$40:$M$40),G11="B List",_xlfn.XLOOKUP(E11,$P$39:$T$39,$P$40:$T$40))} -> 1000000 | M11: 2 | N11: {=_xlfn.IFS(G11="A List",_xlfn.XLOOKUP(E11,$B$39:$F$39,$B$43:$F$43),G11="Supporting",_xlfn.XLOOKUP(E11,$I$39:$M$39,$I$43:$M$43),G11="B List",_xlfn.XLOOKUP(E11,$P$39:$T$39,$P$43:$T$43))} -> 85000 | O11: 10 | P11: {=_xlfn.IFS(G11="A List",_xlfn.XLOOKUP(E11,$B$39:$F$39,$B$45:$F$45),G11="Supporting",_xlfn.XLOOKUP(E11,$I$39:$M$39,$I$45:$M$45),G11="B List",_xlfn.XLOOKUP(E11,$P$39:$T$39,$P$45:$T$45))} -> 35000 | Q11: 3 | R11: {=_xlfn.IFS(G11="A List",_xlfn.XLOOKUP(E11,$B$39:$F$39,$B$44:$F$44),G11="Supporting",_xlfn.XLOOKUP(E11,$I$39:$M$39,$I$44:$M$44),G11="B List",_xlfn.XLOOKUP(E11,$P$39:$T$39,$P$44:$T$44))} -> 55000 | S11: 0 | T11: {=_xlfn.IFS(G11="A List",_xlfn.XLOOKUP(E11,$B$39:$F$39,$B$41:$F$41),G11="Supporting",_xlfn.XLOOKUP(E11,$I$39:$M$39,$I$41:$M$41),G11="B List",_xlfn.XLOOKUP(E11,$P$39:$T$39,$P$41:$T$41))} -> 0 | U11: 0 | V11: {=_xlfn.IFS(G11="A List",_xlfn.XLOOKUP(E11,$B$39:$F$39,$B$42:$F$42),G11="Supporting",_xlfn.XLOOKUP(E11,$I$39:$M$39,$I$42:$M$42),G11="B List",_xlfn.XLOOKUP(E11,$P$39:$T$39,$P$42:$T$42))} -> 0 | W11: 0 | X11: {=_xlfn.IFS(G11="A List",_xlfn.XLOOKUP(E11,$B$39:$F$39,$B$46:$F$46),G11="Supporting",_xlfn.XLOOKUP(E11,$I$39:$M$39,$I$46:$M$46),G11="B List",_xlfn.XLOOKUP(E11,$P$39:$T$39,$P$46:$T$46))} -> 150 | Y11: 94 | Z11: 50 | AA11: 46 | AB11: 51 | AC11: 33 | AD11: 39 | AE11: 26 | AF11: 84 | AG11: 40 | AH11: 14 | AI11: 26 | AJ11: 44 | AK11: 12 | AL11: 4 | AM11: 1 | AN11: 4 | AO11: 16 | AP11: 22 | AQ11: 10 | AR11: 13 | AS11: 70 | AT11: 4 | AU11: 4 | AV11: 8 | AW11: 24 | AX11: 59 | AY11: 17 | AZ11: 21 | BA11: 14 | BB11: 11 | BC11: 3 | BD11: 2 | BE11: 4 | BF11: 9 | BG11: 6 | BH11: 21 | BI11: 7 | BJ11: 4 | BK11: 2 | BL11: 18 | BM11: 17 | BN11: 3 | BO11: 6 | BP11: 25 | BQ11: 15 | BR11: 7 | BS11: 6 | BT11: 7 | BU11: 9 | BV11: 11 | BW11: 20 | BX11: 4 | BY11: 3 | BZ11: 10 | CA11: 14 | CB11: 17 | CC11: 11 | CD11: 12 | CE11: 11 | CF11: 7 | CG11: 37 | CH11: 9 | CI11: 11 | CJ11: 6 | CK11: 18 | CL11: 42 | CM11: 9 | CN11: 6 | CO11: 10 | CP11: 7
A12: 109471 | B12: 10 | C12: 10 | D12: United States | E12: Entertainment | F12: =(0.5*AC12)+(0.3*Z12)+(0.2*AA12) -> 34.2 | G12: {=_xlfn.IFS(F12<24.9,"B List",F12<45,"Supporting",F12>=45,"A List")} -> Supporting | H12: =(K12*L12)+(M12*N12)+(O12*P12)+(Q12*R12)+(S12*T12)+(U12*V12)+(W12*X12) -> 1250000 | I12: =H12/B12 -> 125000 | J12: =LN(I12) -> 11.736069 | K12: 1 | L12: {=_xlfn.IFS(G12="A List",_xlfn.XLOOKUP(E12,$B$39:$F$39,$B$40:$F$40),G12="Supporting",_xlfn.XLOOKUP(E12,$I$39:$M$39,$I$40:$M$40),G12="B List",_xlfn.XLOOKUP(E12,$P$39:$T$39,$P$40:$T$40))} -> 1000000 | M12: 2 | N12: {=_xlfn.IFS(G12="A List",_xlfn.XLOOKUP(E12,$B$39:$F$39,$B$43:$F$43),G12="Supporting",_xlfn.XLOOKUP(E12,$I$39:$M$39,$I$43:$M$43),G12="B List",_xlfn.XLOOKUP(E12,$P$39:$T$39,$P$43:$T$43))} -> 125000 | O12: 0 | P12: {=_xlfn.IFS(G12="A List",_xlfn.XLOOKUP(E12,$B$39:$F$39,$B$45:$F$45),G12="Supporting",_xlfn.XLOOKUP(E12,$I$39:$M$39,$I$45:$M$45),G12="B List",_xlfn.XLOOKUP(E12,$P$39:$T$39,$P$45:$T$45))} -> 35000 | Q12: 0 | R12: {=_xlfn.IFS(G12="A List",_xlfn.XLOOKUP(E12,$B$39:$F$39,$B$44:$F$44),G12="Supporting",_xlfn.XLOOKUP(E12,$I$39:$M$39,$I$44:$M$44),G12="B List",_xlfn.XLOOKUP(E12,$P$39:$T$39,$P$44:$T$44))} -> 50000 | S12: 0 | T12: {=_xlfn.IFS(G12="A List",_xlfn.XLOOKUP(E12,$B$39:$F$39,$B$41:$F$41),G12="Supporting",_xlfn.XLOOKUP(E12,$I$39:$M$39,$I$41:$M$41),G12="B List",_xlfn.XLOOKUP(E12,$P$39:$T$39,$P$41:$T$41))} -> 0 | U12: 0 | V12: {=_xlfn.IFS(G12="A List",_xlfn.XLOOKUP(E12,$B$39:$F$39,$B$42:$F$42),G12="Supporting",_xlfn.XLOOKUP(E12,$I$39:$M$39,$I$42:$M$42),G12="B List",_xlfn.XLOOKUP(E12,$P$39:$T$39,$P$42:$T$42))} -> 0 | W12: 0 | X12: {=_xlfn.IFS(G12="A List",_xlfn.XLOOKUP(E12,$B$39:$F$39,$B$46:$F$46),G12="Supporting",_xlfn.XLOOKUP(E12,$I$39:$M$39,$I$46:$M$46),G12="B List",_xlfn.XLOOKUP(E12,$P$39:$T$39,$P$46:$T$46))} -> 0 | Y12: 97 | Z12: 29 | AA12: 70 | AB12: 45 | AC12: 23 | AD12: 19 | AE12: 27 | AF12: 96 | AG12: 72 | AH12: 37 | AI12: 35 | AJ12: 24 | AK12: 2 | AL12: 2 | AM12: 0 | AN12: 2 | AO12: 4 | AP12: 31 | AQ12: 14 | AR12: 17 | AS12: 66 | AT12: 2 | AU12: 1 | AV12: 3 | AW12: 45 | AX12: 52 | AY12: 3 | AZ12: 23 | BA12: 15 | BB12: 15 | BC12: 2 | BD12: 3 | BE12: 2 | BF12: 11 | BG12: 8 | BH12: 12 | BI12: 14 | BJ12: 0 | BK12: 4 | BL12: 15 | BM12: 19 | BN12: 2 | BO12: 8 | BP12: 21 | BQ12: 14 | BR12: 13 | BS12: 4 | BT12: 26 | BU12: 14 | BV12: 11 | BW12: 33 | BX12: 1 | BY12: 44 | BZ12: 11 | CA12: 26 | CB12: 10 | CC12: 9 | CD12: 17 | CE12: 20 | CF12: 1 | CG12: 2 | CH12: 15 | CI12: 4 | CJ12: 9 | CK12: 13 | CL12: 53 | CM12: 3 | CN12: 6 | CO12: 16 | CP12: 19
A13: 863003 | B13: 22 | C13: 600 | D13: Global | E13: Athlete | F13: =(0.5*AC13)+(0.3*Z13)+(0.2*AA13) -> 34.2 | G13: {=_xlfn.IFS(F13<24.9,"B List",F13<45,"Supporting",F13>=45,"A List")} -> Supporting | H13: =(K13*L13)+(M13*N13)+(O13*P13)+(Q13*R13)+(S13*T13)+(U13*V13)+(W13*X13) -> 1385000 | I13: =H13/B13 -> 62954.545 | J13: =LN(I13) -> 11.050168 | K13: 1 | L13: {=_xlfn.IFS(G13="A List",_xlfn.XLOOKUP(E13,$B$39:$F$39,$B$40:$F$40),G13="Supporting",_xlfn.XLOOKUP(E13,$I$39:$M$39,$I$40:$M$40),G13="B List",_xlfn.XLOOKUP(E13,$P$39:$T$39,$P$40:$T$40))} -> 1000000 | M13: 2 | N13: {=_xlfn.IFS(G13="A List",_xlfn.XLOOKUP(E13,$B$39:$F$39,$B$43:$F$43),G13="Supporting",_xlfn.XLOOKUP(E13,$I$39:$M$39,$I$43:$M$43),G13="B List",_xlfn.XLOOKUP(E13,$P$39:$T$39,$P$43:$T$43))} -> 85000 | O13: 3 | P13: {=_xlfn.IFS(G13="A List",_xlfn.XLOOKUP(E13,$B$39:$F$39,$B$45:$F$45),G13="Supporting",_xlfn.XLOOKUP(E13,$I$39:$M$39,$I$45:$M$45),G13="B List",_xlfn.XLOOKUP(E13,$P$39:$T$39,$P$45:$T$45))} -> 35000 | Q13: 2 | R13: {=_xlfn.IFS(G13="A List",_xlfn.XLOOKUP(E13,$B$39:$F$39,$B$44:$F$44),G13="Supporting",_xlfn.XLOOKUP(E13,$I$39:$M$39,$I$44:$M$44),G13="B List",_xlfn.XLOOKUP(E13,$P$39:$T$39,$P$44:$T$44))} -> 55000 | S13: 0 | T13: {=_xlfn.IFS(G13="A List",_xlfn.XLOOKUP(E13,$B$39:$F$39,$B$41:$F$41),G13="Supporting",_xlfn.XLOOKUP(E13,$I$39:$M$39,$I$41:$M$41),G13="B List",_xlfn.XLOOKUP(E13,$P$39:$T$39,$P$41:$T$41))} -> 0 | U13: 0 | V13: {=_xlfn.IFS(G13="A List",_xlfn.XLOOKUP(E13,$B$39:$F$39,$B$42:$F$42),G13="Supporting",_xlfn.XLOOKUP(E13,$I$39:$M$39,$I$42:$M$42),G13="B List",_xlfn.XLOOKUP(E13,$P$39:$T$39,$P$42:$T$42))} -> 0 | W13: 0 | X13: {=_xlfn.IFS(G13="A List",_xlfn.XLOOKUP(E13,$B$39:$F$39,$B$46:$F$46),G13="Supporting",_xlfn.XLOOKUP(E13,$I$39:$M$39,$I$46:$M$46),G13="B List",_xlfn.XLOOKUP(E13,$P$39:$T$39,$P$46:$T$46))} -> 150 | Y13: 92 | Z13: 32 | AA13: 63 | AB13: 80 | AC13: 24 | AD13: 28 | AE13: 20 | AF13: 87 | AG13: 57 | AH13: 27 | AI13: 29 | AJ13: 31 | AK13: 6 | AL13: 5 | AM13: 2 | AN13: 7 | AO13: 13 | AP13: 42 | AQ13: 24 | AR13: 18 | AS13: 52 | AT13: 3 | AU13: 3 | AV13: 6 | AW13: 38 | AX13: 47 | AY13: 16 | AZ13: 40 | BA13: 30 | BB13: 22 | BC13: 6 | BD13: 4 | BE13: 3 | BF13: 10 | BG13: 5 | BH13: 10 | BI13: 6 | BJ13: 3 | BK13: 4 | BL13: 11 | BM13: 14 | BN13: 4 | BO13: 15 | BP13: 33 | BQ13: 26 | BR13: 12 | BS13: 5 | BT13: 4 | BU13: 20 | BV13: 22 | BW13: 32 | BX13: 3 | BY13: 6 | BZ13: 8 | CA13: 31 | CB13: 32 | CC13: 25 | CD13: 19 | CE13: 19 | CF13: 5 | CG13: 42 | CH13: 17 | CI13: 6 | CJ13: 8 | CK13: 13 | CL13: 54 | CM13: 13 | CN13: 13 | CO13: 21 | CP13: 13
A14: 784333 | B14: 5 | C14: 20 | D14: United States | E14: Entertainment | F14: =(0.5*AC14)+(0.3*Z14)+(0.2*AA14) -> 32.3 | G14: {=_xlfn.IFS(F14<24.9,"B List",F14<45,"Supporting",F14>=45,"A List")} -> Supporting | H14: =(K14*L14)+(M14*N14)+(O14*P14)+(Q14*R14)+(S14*T14)+(U14*V14)+(W14*X14) -> 230000 | I14: =H14/B14 -> 46000 | J14: =LN(I14) -> 10.736397 | K14: 0 | L14: {=_xlfn.IFS(G14="A List",_xlfn.XLOOKUP(E14,$B$39:$F$39,$B$40:$F$40),G14="Supporting",_xlfn.XLOOKUP(E14,$I$39:$M$39,$I$40:$M$40),G14="B List",_xlfn.XLOOKUP(E14,$P$39:$T$39,$P$40:$T$40))} -> 1000000 | M14: 1 | N14: {=_xlfn.IFS(G14="A List",_xlfn.XLOOKUP(E14,$B$39:$F$39,$B$43:$F$43),G14="Supporting",_xlfn.XLOOKUP(E14,$I$39:$M$39,$I$43:$M$43),G14="B List",_xlfn.XLOOKUP(E14,$P$39:$T$39,$P$43:$T$43))} -> 125000 | O14: 3 | P14: {=_xlfn.IFS(G14="A List",_xlfn.XLOOKUP(E14,$B$39:$F$39,$B$45:$F$45),G14="Supporting",_xlfn.XLOOKUP(E14,$I$39:$M$39,$I$45:$M$45),G14="B List",_xlfn.XLOOKUP(E14,$P$39:$T$39,$P$45:$T$45))} -> 35000 | Q14: 0 | R14: {=_xlfn.IFS(G14="A List",_xlfn.XLOOKUP(E14,$B$39:$F$39,$B$44:$F$44),G14="Supporting",_xlfn.XLOOKUP(E14,$I$39:$M$39,$I$44:$M$44),G14="B List",_xlfn.XLOOKUP(E14,$P$39:$T$39,$P$44:$T$44))} -> 50000 | S14: 0 | T14: {=_xlfn.IFS(G14="A List",_xlfn.XLOOKUP(E14,$B$39:$F$39,$B$41:$F$41),G14="Supporting",_xlfn.XLOOKUP(E14,$I$39:$M$39,$I$41:$M$41),G14="B List",_xlfn.XLOOKUP(E14,$P$39:$T$39,$P$41:$T$41))} -> 0 | U14: 0 | V14: {=_xlfn.IFS(G14="A List",_xlfn.XLOOKUP(E14,$B$39:$F$39,$B$42:$F$42),G14="Supporting",_xlfn.XLOOKUP(E14,$I$39:$M$39,$I$42:$M$42),G14="B List",_xlfn.XLOOKUP(E14,$P$39:$T$39,$P$42:$T$42))} -> 0 | W14: 0 | X14: {=_xlfn.IFS(G14="A List",_xlfn.XLOOKUP(E14,$B$39:$F$39,$B$46:$F$46),G14="Supporting",_xlfn.XLOOKUP(E14,$I$39:$M$39,$I$46:$M$46),G14="B List",_xlfn.XLOOKUP(E14,$P$39:$T$39,$P$46:$T$46))} -> 0 | Y14: 95 | Z14: 26 | AA14: 65 | AB14: 40 | AC14: 23 | AD14: 20 | AE14: 26 | AF14: 94 | AG14: 68 | AH14: 29 | AI14: 38 | AJ14: 27 | AK14: 3 | AL14: 2 | AM14: 1 | AN14: 3 | AO14: 6 | AP14: 30 | AQ14: 13 | AR14: 17 | AS14: 66 | AT14: 2 | AU14: 2 | AV14: 4 | AW14: 43 | AX14: 50 | AY14: 7 | AZ14: 20 | BA14: 15 | BB14: 8 | BC14: 1 | BD14: 2 | BE14: 3 | BF14: 15 | BG14: 13 | BH14: 12 | BI14: 3 | BJ14: 3 | BK14: 6 | BL14: 17 | BM14: 8 | BN14: 1 | BO14: 7 | BP14: 17 | BQ14: 18 | BR14: 11 | BS14: 9 | BT14: 17 | BU14: 10 | BV14: 9 | BW14: 18 | BX14: 2 | BY14: 57 | BZ14: 2 | CA14: 26 | CB14: 5 | CC14: 6 | CD14: 13 | CE14: 13 | CF14: 4 | CG14: 5 | CH14: 10 | CI14: 2 | CJ14: 9 | CK14: 4 | CL14: 36 | CM14: 5 | CN14: 5 | CO14: 9 | CP14: 10
... A36: 829240 | B36: 12 | C36: 150 | D36: United States | E36: Athlete | F36: =(0.5*AC36)+(0.3*Z36)+(0.2*AA36) -> 12.5 | G36: {=_xlfn.IFS(F36<24.9,"B List",F36<45,"Supporting",F36>=45,"A List")} -> B List | H36: =(K36*L36)+(M36*N36)+(O36*P36)+(Q36*R36)+(S36*T36)+(U36*V36)+(W36*X36) -> 136000 | I36: =H36/B36 -> 11333.333 | J36: =LN(I36) -> 9.3355035 | K36: 0 | L36: {=_xlfn.IFS(G36="A List",_xlfn.XLOOKUP(E36,$B$39:$F$39,$B$40:$F$40),G36="Supporting",_xlfn.XLOOKUP(E36,$I$39:$M$39,$I$40:$M$40),G36="B List",_xlfn.XLOOKUP(E36,$P$39:$T$39,$P$40:$T$40))} -> 350000 | M36: 2 | N36: {=_xlfn.IFS(G36="A List",_xlfn.XLOOKUP(E36,$B$39:$F$39,$B$43:$F$43),G36="Supporting",_xlfn.XLOOKUP(E36,$I$39:$M$39,$I$43:$M$43),G36="B List",_xlfn.XLOOKUP(E36,$P$39:$T$39,$P$43:$T$43))} -> 20000 | O36: 5 | P36: {=_xlfn.IFS(G36="A List",_xlfn.XLOOKUP(E36,$B$39:$F$39,$B$45:$F$45),G36="Supporting",_xlfn.XLOOKUP(E36,$I$39:$M$39,$I$45:$M$45),G36="B List",_xlfn.XLOOKUP(E36,$P$39:$T$39,$P$45:$T$45))} -> 12000 | Q36: 2 | R36: {=_xlfn.IFS(G36="A List",_xlfn.XLOOKUP(E36,$B$39:$F$39,$B$44:$F$44),G36="Supporting",_xlfn.XLOOKUP(E36,$I$39:$M$39,$I$44:$M$44),G36="B List",_xlfn.XLOOKUP(E36,$P$39:$T$39,$P$44:$T$44))} -> 18000 | S36: 0 | T36: {=_xlfn.IFS(G36="A List",_xlfn.XLOOKUP(E36,$B$39:$F$39,$B$41:$F$41),G36="Supporting",_xlfn.XLOOKUP(E36,$I$39:$M$39,$I$41:$M$41),G36="B List",_xlfn.XLOOKUP(E36,$P$39:$T$39,$P$41:$T$41))} -> 0 | U36: 0 | V36: {=_xlfn.IFS(G36="A List",_xlfn.XLOOKUP(E36,$B$39:$F$39,$B$42:$F$42),G36="Supporting",_xlfn.XLOOKUP(E36,$I$39:$M$39,$I$42:$M$42),G36="B List",_xlfn.XLOOKUP(E36,$P$39:$T$39,$P$42:$T$42))} -> 0 | W36: 0 | X36: {=_xlfn.IFS(G36="A List",_xlfn.XLOOKUP(E36,$B$39:$F$39,$B$46:$F$46),G36="Supporting",_xlfn.XLOOKUP(E36,$I$39:$M$39,$I$46:$M$46),G36="B List",_xlfn.XLOOKUP(E36,$P$39:$T$39,$P$46:$T$46))} -> 60 | Y36: 6 | Z36: 21 | AA36: 26 | AB36: 32 | AC36: 2 | AD36: 1 | AE36: 3 | AF36: 84 | AG36: 48 | AH36: 21 | AI36: 26 | AJ36: 37 | AK36: 9 | AL36: 0 | AM36: 7 | AN36: 7 | AO36: 16 | AP36: 38 | AQ36: 13 | AR36: 25 | AS36: 52 | AT36: 6 | AU36: 4 | AV36: 10 | AW36: 32 | AX36: 57 | AY36: 10 | AZ36: 40 | BA36: 22 | BB36: 18 | BC36: 0 | BD36: 10 | BE36: 4 | BF36: 17 | BG36: 10 | BH36: 16 | BI36: 3 | BJ36: 0 | BK36: 11 | BL36: 19 | BM36: 27 | BN36: 7 | BO36: 6 | BP36: 15 | BQ36: 26 | BR36: 16 | BS36: 10 | BT36: 10 | BU36: 14 | BV36: 21 | BW36: 14 | BX36: 4 | BY36: 0 | BZ36: 5 | CA36: 29 | CB36: 1 | CC36: 6 | CD36: 24 | CE36: 17 | CF36: 3 | CG36: 11 | CH36: 11 | CI36: 0 | CJ36: 17 | CK36: 6 | CL36: 15 | CM36: 0 | CN36: 11 | CO36: 6 | CP36: 0
A39: A List | B39: Entertainment | C39: Music Artist | D39: Athlete | E39: TV Personality | F39: Comedian | H39: Supporting | I39: Entertainment | J39: Music Artist | K39: Athlete | L39: TV Personality | M39: Comedian | O39: B List | P39: Entertainment | Q39: Music Artist | R39: Athlete | S39: TV Personality | T39: Comedian
A40: Super Bowl | B40: 2500000 | C40: 2500000 | D40: 2500000 | E40: 2500000 | F40: 2500000 | H40: Super Bowl | I40: 1000000 | J40: 1000000 | K40: 1000000 | L40: 1000000 | M40: 1000000 | O40: Super Bowl | P40: 350000 | Q40: 350000 | R40: 350000 | S40: 350000 | T40: 350000
A41: Tour Sponsorship | B41: 0 | C41: 1500000 | D41: 0 | E41: 0 | F41: 500000 | H41: Tour Sponsorship | I41: 0 | J41: 500000 | K41: 0 | L41: 0 | M41: 175000 | O41: Tour Sponsorship | P41: 0 | Q41: 125000 | R41: 0 | S41: 0 | T41: 50000
A42: Live Performance | B42: 0 | C42: 1000000 | D42: 0 | E42: 0 | F42: 0 | H42: Live Performance | I42: 0 | J42: 500000 | K42: 0 | L42: 0 | M42: 0 | O42: Live Performance | P42: 0 | Q42: 175000 | R42: 0 | S42: 0 | T42: 0
A43: Production Day | B43: 300000 | C43: 250000 | D43: 225000 | E43: 180000 | F43: 220000 | H43: Production Day | I43: 125000 | J43: 100000 | K43: 85000 | L43: 75000 | M43: 90000 | O43: Production Day | P43: 30000 | Q43: 25000 | R43: 20000 | S43: 20000 | T43: 25000
A44: Appearance | B44: 150000 | C44: 175000 | D44: 175000 | E44: 100000 | F44: 80000 | H44: Appearance | I44: 50000 | J44: 60000 | K44: 55000 | L44: 40000 | M44: 30000 | O44: Appearance | P44: 15000 | Q44: 20000 | R44: 18000 | S44: 12000 | T44: 10000
A45: Social Media Post | B45: 70000 | C45: 80000 | D45: 75000 | E45: 55000 | F45: 50000 | H45: Social Media Post | I45: 35000 | J45: 40000 | K45: 35000 | L45: 30000 | M45: 25000 | O45: Social Media Post | P45: 13000 | Q45: 15000 | R45: 12000 | S45: 12000 | T45: 10000
A46: Tickets | B46: 0 | C46: 300 | D46: 400 | E46: 0 | F46: 160 | H46: Tickets | I46: 0 | J46: 150 | K46: 150 | L46: 0 | M46: 90 | O46: Tickets | P46: 0 | Q46: 75 | R46: 60 | S46: 0 | T46: 45

Sheet Regression Analysis (SB)
A2: Celebrity ID | B2: Ln(Estimated Monthly Cost) | C2: Shared, Posted or Commented | D2: Distinctive Voice | E2: Glamorous | F2: Unique | H2: SUMMARY OUTPUT
A3: 363670 | B3: 12.644328 | C3: 12 | D3: 30 | E3: 3 | F3: 20
A4: 103507 | B4: 11.911422 | C4: 7 | D4: 14 | E4: 5 | F4: 9 | H4: Regression Statistics
A5: 554026 | B5: 13.027442 | C5: 15 | D5: 27 | E5: 3 | F5: 24 | H5: Multiple R | I5: 0.96394133
A6: 124932 | B6: 12.506177 | C6: 7 | D6: 18 | E6: 4 | F6: 11 | H6: R Square | I6: 0.92918289
A7: 245103 | B7: 11.526719 | C7: 10 | D7: 19 | E7: 2 | F7: 9 | H7: Adjusted R Square | I7: 0.89770863
A8: 741355 | B8: 11.159222 | C8: 11 | D8: 7 | E8: 10 | F8: 10 | H8: Standard Error | I8: 0.3100829
A9: 109471 | B9: 11.736069 | C9: 15 | D9: 26 | E9: 11 | F9: 16 | H9: Observations | I9: 14
A10: 863003 | B10: 11.050168 | C10: 22 | D10: 4 | E10: 8 | F10: 21
A11: 595416 | B11: 12.323856 | C11: 6 | D11: 13 | E11: 1 | F11: 6 | H11: ANOVA
A12: 583792 | B12: 10.103021 | C12: 32 | D12: 10 | E12: 6 | F12: 14 | I12: df | J12: SS | K12: MS | L12: F | M12: Significance F
A13: 715535 | B13: 11.151477 | C13: 10 | D13: 7 | E13: 2 | F13: 7 | H13: Regression | I13: 4 | J13: 11.354321 | K13: 2.8385803 | L13: 29.521985 | M13: 3.4678671e-05
A14: 741587 | B14: 10.46072 | C14: 19 | D14: 2 | E14: 9 | F14: 13 | H14: Residual | I14: 9 | J14: 0.86536265 | K14: 0.096151406
A15: 285355 | B15: 9.9950027 | C15: 28 | D15: 3 | E15: 6 | F15: 3 | H15: Total | I15: 13 | J15: 12.219684
A16: 791193 | B16: 10.509623 | C16: 34 | D16: 19 | E16: 5 | F16: 14
I17: Coefficients | J17: Standard Error | K17: t Stat | L17: P-value | M17: Lower 95% | N17: Upper 95% | O17: Lower 95.0% | P17: Upper 95.0%
H18: Intercept | I18: 11.663706 | J18: 0.28582737 | K18: 40.806818 | L18: 1.5874473e-11 | M18: 11.017119 | N18: 12.310292 | O18: 11.017119 | P18: 12.310292
H19: Shared, Posted or Commented | I19: -0.067812839 | J19: 0.01014985 | K19: -6.6811666 | L19: 9.0458255e-05 | M19: -0.090773395 | N19: -0.044852283 | O19: -0.090773395 | P19: -0.044852283
H20: Distinctive Voice | I20: 0.034975469 | J20: 0.012517443 | K20: 2.7941385 | L20: 0.020911945 | M20: 0.006659046 | N20: 0.063291892 | O20: 0.006659046 | P20: 0.063291892
H21: Glamorous | I21: -0.057651996 | J21: 0.031268559 | K21: -1.8437689 | L21: 0.098320694 | M21: -0.12838639 | N21: 0.013082398 | O21: -0.12838639 | P21: 0.013082398
H22: Unique | I22: 0.054454668 | J22: 0.018563192 | K22: 2.9334754 | L22: 0.016662566 | M22: 0.01246181 | N22: 0.096447526 | O22: 0.01246181 | P22: 0.096447526

Sheet Regression Analysis (No SB)
A2: Celebrity ID | B2: Ln(Estimated Monthly Cost) | C2: Fan | D2: Activist | E2: Classy | F2: Funny | G2: Interesting | H2: Sincere | I2: Unique | K2: SUMMARY OUTPUT
A3: 697021 | B3: 11.644751 | C3: 34 | D3: 4 | E3: 6 | F3: 21 | G3: 13 | H3: 8 | I3: 16
A4: 159642 | B4: 10.336352 | C4: 23 | D4: 1 | E4: 8 | F4: 6 | G4: 12 | H4: 6 | I4: 10 | K4: Regression Statistics
A5: 965832 | B5: 10.582648 | C5: 29 | D5: 3 | E5: 11 | F5: 10 | G5: 13 | H5: 4 | I5: 7 | K5: Multiple R | L5: 0.9876922
A6: 784333 | B6: 10.736397 | C6: 43 | D6: 1 | E6: 8 | F6: 57 | G6: 13 | H6: 9 | I6: 9 | K6: R Square | L6: 0.97553589
A7: 743158 | B7: 9.9835303 | C7: 29 | D7: 3 | E7: 8 | F7: 7 | G7: 13 | H7: 6 | I7: 8 | K7: Adjusted R Square | L7: 0.96126516
A8: 775978 | B8: 10.802971 | C8: 32 | D8: 3 | E8: 12 | F8: 4 | G8: 13 | H8: 6 | I8: 10 | K8: Standard Error | L8: 0.21212226
A9: 155627 | B9: 8.9001854 | C9: 50 | D9: 8 | E9: 10 | F9: 8 | G9: 16 | H9: 5 | I9: 9 | K9: Observations | L9: 20
A10: 303824 | B10: 8.4832916 | C10: 43 | D10: 3 | E10: 6 | F10: 16 | G10: 17 | H10: 10 | I10: 8
A11: 384868 | B11: 9.1413475 | C11: 48 | D11: 8 | E11: 7 | F11: 5 | G11: 6 | H11: 2 | I11: 4 | K11: ANOVA
A12: 412740 | B12: 12.154779 | C12: 25 | D12: 1 | E12: 10 | F12: 3 | G12: 22 | H12: 9 | I12: 24 | L12: df | M12: SS | N12: MS | O12: F | P12: Significance F
A13: 300578 | B13: 8.9446372 | C13: 42 | D13: 2 | E13: 9 | F13: 32 | G13: 15 | H13: 5 | I13: 4 | K13: Regression | L13: 7 | M13: 21.531168 | N13: 3.0758812 | O13: 68.359213 | P13: 1.0136297e-08
A14: 264175 | B14: 9.3206884 | C14: 30 | D14: 1 | E14: 4 | F14: 10 | G14: 19 | H14: 5 | I14: 9 | K14: Residual | L14: 12 | M14: 0.53995025 | N14: 0.044995854
A15: 407054 | B15: 9.9034876 | C15: 44 | D15: 3 | E15: 25 | F15: 8 | G15: 14 | H15: 11 | I15: 7 | K15: Total | L15: 19 | M15: 22.071119
A16: 144967 | B16: 8.5606783 | C16: 49 | D16: 2 | E16: 15 | F16: 10 | G16: 14 | H16: 6 | I16: 7
A17: 335473 | B17: 8.753582 | C17: 38 | D17: 0 | E17: 15 | F17: 3 | G17: 14 | H17: 7 | I17: 6 | L17: Coefficients | M17: Standard Error | N17: t Stat | O17: P-value | P17: Lower 95% | Q17: Upper 95% | R17: Lower 95.0% | S17: Upper 95.0%
A18: 396536 | B18: 9.798127 | C18: 47 | D18: 3 | E18: 6 | F18: 6 | G18: 21 | H18: 3 | I18: 20 | K18: Intercept | L18: 11.224007 | M18: 0.34687651 | N18: 32.357357 | O18: 4.7989587e-13 | P18: 10.468228 | Q18: 11.979786 | R18: 10.468228 | S18: 11.979786
A19: 660137 | B19: 10.210513 | C19: 53 | D19: 5 | E19: 8 | F19: 16 | G19: 7 | H19: 0 | I19: 12 | K19: Fan | L19: -0.088132718 | M19: 0.0065241377 | N19: -13.508715 | O19: 1.2790491e-08 | P19: -0.10234759 | Q19: -0.073917843 | R19: -0.10234759 | S19: -0.073917843
A20: 448227 | B20: 8.2940496 | C20: 40 | D20: 3 | E20: 6 | F20: 17 | G20: 25 | H20: 16 | I20: 11 | K20: Activist | L20: 0.14879706 | M20: 0.032955093 | N20: 4.5151462 | O20: 0.00070775166 | P20: 0.076994085 | Q20: 0.22060005 | R20: 0.076994085 | S20: 0.22060005
A21: 714387 | B21: 10.849337 | C21: 22 | D21: 2 | E21: 16 | F21: 20 | G21: 13 | H21: 3 | I21: 3 | K21: Classy | L21: 0.086917272 | M21: 0.011717415 | N21: 7.4177855 | O21: 8.0783229e-06 | P21: 0.061387218 | Q21: 0.11244733 | R21: 0.061387218 | S21: 0.11244733
A22: 829240 | B22: 9.3355035 | C22: 32 | D22: 0 | E22: 27 | F22: 0 | G22: 17 | H22: 17 | I22: 6 | K22: Funny | L22: 0.042134615 | M22: 0.0046467173 | N22: 9.0676087 | O22: 1.0201172e-06 | P22: 0.032010287 | Q22: 0.052258942 | R22: 0.032010287 | S22: 0.052258942
K23: Interesting | L23: -0.098392943 | M23: 0.017149511 | N23: -5.7373614 | O23: 9.3470478e-05 | P23: -0.13575852 | Q23: -0.061027369 | R23: -0.13575852 | S23: -0.061027369
K24: Sincere | L24: -0.044658907 | M24: 0.017391807 | N24: -2.5678129 | O24: 0.024644598 | P24: -0.082552399 | Q24: -0.0067654141 | R24: -0.082552399 | S24: -0.0067654141
K25: Unique | L25: 0.18894599 | M25: 0.011602309 | N25: 16.285205 | O25: 1.5127994e-09 | P25: 0.16366673 | Q25: 0.21422525 | R25: 0.16366673 | S25: 0.21422525

Sheet Calculator and Test Cases 
A1: Superbowl Appearance
B9: Calculator | G9: 554026
B10: Coefficients | C10: Input Value | G10: Coefficients | H10: Input Value
A11: ='Regression Analysis (SB)'!H18 -> Intercept | B11: ='Regression Analysis (SB)'!$I$18 -> 11.663706 | F11: =A11 -> Intercept | G11: =B11 -> 11.663706
A12: ='Regression Analysis (SB)'!H19 -> Shared, Posted or Commented | B12: ='Regression Analysis (SB)'!$I$19 -> -0.067812839 | C12: 20 | F12: =A12 -> Shared, Posted or Commented | G12: =B12 -> -0.067812839 | H12: 15
A13: ='Regression Analysis (SB)'!H20 -> Distinctive Voice | B13: ='Regression Analysis (SB)'!$I$20 -> 0.034975469 | C13: 30 | F13: =A13 -> Distinctive Voice | G13: =B13 -> 0.034975469 | H13: 27
A14: ='Regression Analysis (SB)'!H21 -> Glamorous | B14: ='Regression Analysis (SB)'!$I$21 -> -0.057651996 | C14: 5 | F14: =A14 -> Glamorous | G14: =B14 -> -0.057651996 | H14: 3
A15: ='Regression Analysis (SB)'!H22 -> Unique | B15: ='Regression Analysis (SB)'!$I$22 -> 0.054454668 | C15: 26 | F15: =A15 -> Unique | G15: =B15 -> 0.054454668 | H15: 24
A16: Term Length | C16: 24 | F16: =A16 -> Term Length | H16: 18
B17: Monthly Cost | C17: =EXP(B11+SUMPRODUCT(B12:B15,C12:C15)) -> 264150.51 | G17: Monthly Cost | H17: =EXP(G11+SUMPRODUCT(G12:G15,H12:H15)) -> 335979.95
B18: Total Cost | C18: =C17*C16 -> 6339612.3 | G18: Total Cost | H18: =H17*H16 -> 6047639.2
B19: Non- Exclusive | C19: =C18*0.75 -> 4754709.2 | G19: Non- Exclusive | H19: =H18*0.75 -> 4535729.4
A21: No Superbowl Appearance
B29: Calculator | G29: 159642 | L29: 965832
B30: Coefficients | C30: Input Value | G30: Coefficients | H30: Input Value | L30: Coefficients | M30: Input Value
A31: ='Regression Analysis (No SB)'!K18 -> Intercept | B31: ='Regression Analysis (No SB)'!L18 -> 11.224007 | F31: =A31 -> Intercept | G31: =B31 -> 11.224007 | K31: =A31 -> Intercept | L31: =B31 -> 11.224007
A32: ='Regression Analysis (No SB)'!K19 -> Fan | B32: ='Regression Analysis (No SB)'!L19 -> -0.088132718 | F32: =A32 -> Fan | G32: =B32 -> -0.088132718 | H32: 23 | K32: =A32 -> Fan | L32: =B32 -> -0.088132718 | M32: 29
A33: ='Regression Analysis (No SB)'!K20 -> Activist | B33: ='Regression Analysis (No SB)'!L20 -> 0.14879706 | F33: =A33 -> Activist | G33: =B33 -> 0.14879706 | H33: 1 | K33: =A33 -> Activist | L33: =B33 -> 0.14879706 | M33: 3
A34: ='Regression Analysis (No SB)'!K21 -> Classy | B34: ='Regression Analysis (No SB)'!L21 -> 0.086917272 | F34: =A34 -> Classy | G34: =B34 -> 0.086917272 | H34: 8 | K34: =A34 -> Classy | L34: =B34 -> 0.086917272 | M34: 11
A35: ='Regression Analysis (No SB)'!K22 -> Funny | B35: ='Regression Analysis (No SB)'!L22 -> 0.042134615 | F35: =A35 -> Funny | G35: =B35 -> 0.042134615 | H35: 6 | K35: =A35 -> Funny | L35: =B35 -> 0.042134615 | M35: 10
A36: ='Regression Analysis (No SB)'!K23 -> Interesting | B36: ='Regression Analysis (No SB)'!L23 -> -0.098392943 | F36: =A36 -> Interesting | G36: =B36 -> -0.098392943 | H36: 12 | K36: =A36 -> Interesting | L36: =B36 -> -0.098392943 | M36: 13
A37: ='Regression Analysis (No SB)'!K24 -> Sincere | B37: ='Regression Analysis (No SB)'!L24 -> -0.044658907 | F37: =A37 -> Sincere | G37: =B37 -> -0.044658907 | H37: 6 | K37: =A37 -> Sincere | L37: =B37 -> -0.044658907 | M37: 4
A38: ='Regression Analysis (No SB)'!K25 -> Unique | B38: ='Regression Analysis (No SB)'!L25 -> 0.18894599 | F38: =A38 -> Unique | G38: =B38 -> 0.18894599 | H38: 10 | K38: =A38 -> Unique | L38: =B38 -> 0.18894599 | M38: 7
A39: Term Length | F39: Term Length | H39: 12 | K39: =A39 -> Term Length | M39: 9
B40: Monthly Cost | C40: =EXP(B31+SUMPRODUCT(B32:B38,C32:C38)) -> 74907.325 | G40: Monthly Cost | H40: =EXP(G31+SUMPRODUCT(G32:G38,H32:H38)) -> 45921.492 | L40: Monthly Cost | M40: =EXP(L31+SUMPRODUCT(L32:L38,M32:M38)) -> 31472.314
B41: Total Cost | C41: =C40*C39 -> 0 | G41: Total Cost | H41: =H40*H39 -> 551057.9 | L41: Total Cost | M41: =M40*M39 -> 283250.83
B42: Non- Exclusive | C42: =C41*0.75 -> 0 | G42: Non- Exclusive | H42: =H41*0.75 -> 413293.43 | L42: Non- Exclusive | M42: =M41*0.75 -> 212438.12
A44: Deal Package Designer
F47: 554026 | K47: 159642 | P47: 965832
A48: Category | B48: Select One | F48: Category | G48: Music Artist | K48: Category | L48: Athlete | P48: Category | Q48: Entertainment
A49: Tier | B49: Select One | F49: Tier | G49: A List | K49: Tier | L49: Supporting | P49: Tier | Q49: Supporting
A51: Deliverable | B51: Proposed Qty | C51: Unit Price | D51: Line Total | F51: Deliverable | G51: Proposed Qty | H51: Unit Price | I51: Line Total | K51: Deliverable | L51: Proposed Qty | M51: Unit Price | N51: Line Total | P51: Deliverable | Q51: Proposed Qty | R51: Unit Price | S51: Line Total
A52: Super Bowl | C52: {=IF($B$49="A List",INDEX('Cleaned Data'!$B$40:$F$40,MATCH(TRIM($B$48),TRIM('Cleaned Data'!$B$39:$F$39),0)),IF($B$49="Supporting",INDEX('Cleaned Data'!$I$40:$M$40,MATCH(TRIM($B$48),TRIM('Cleaned Data'!$I$39:$M$39),0)),INDEX('Cleaned Data'!$P$40:$T$40,MATCH(TRIM($B$48),TRIM('Cleaned Data'!$P$39:$T$39),0))))} -> #N/A | D52: =B52*C52 -> #N/A | F52: Super Bowl | G52: 1 | H52: {=IF($G$49="A List",INDEX('Cleaned Data'!$B$40:$F$40,MATCH(TRIM($G$48),TRIM('Cleaned Data'!$B$39:$F$39),0)),IF($G$49="Supporting",INDEX('Cleaned Data'!$I$40:$M$40,MATCH(TRIM($G$48),TRIM('Cleaned Data'!$I$39:$M$39),0)),INDEX('Cleaned Data'!$P$40:$T$40,MATCH(TRIM($G$48),TRIM('Cleaned Data'!$P$39:$T$39),0))))} -> 2500000 | I52: =G52*H52 -> 2500000 | K52: Super Bowl | L52: 0 | M52: {=IF($L$49="A List",INDEX('Cleaned Data'!$B$40:$F$40,MATCH(TRIM($L$48),TRIM('Cleaned Data'!$B$39:$F$39),0)),IF($L$49="Supporting",INDEX('Cleaned Data'!$I$40:$M$40,MATCH(TRIM($L$48),TRIM('Cleaned Data'!$I$39:$M$39),0)),INDEX('Cleaned Data'!$P$40:$T$40,MATCH(TRIM($L$48),TRIM('Cleaned Data'!$P$39:$T$39),0))))} -> 1000000 | N52: =L52*M52 -> 0 | P52: Super Bowl | Q52: 0 | R52: {=IF($Q$49="A List",INDEX('Cleaned Data'!$B$40:$F$40,MATCH(TRIM($Q$48),TRIM('Cleaned Data'!$B$39:$F$39),0)),IF($Q$49="Supporting",INDEX('Cleaned Data'!$I$40:$M$40,MATCH(TRIM($Q$48),TRIM('Cleaned Data'!$I$39:$M$39),0)),INDEX('Cleaned Data'!$P$40:$T$40,MATCH(TRIM($Q$48),TRIM('Cleaned Data'!$P$39:$T$39),0))))} -> 1000000 | S52: =Q52*R52 -> 0
A53: Production Days | C53: {=IF($B$49="A List",INDEX('Cleaned Data'!$B$43:$F$43,MATCH(TRIM($B$48),TRIM('Cleaned Data'!$B$39:$F$39),0)),IF($B$49="Supporting",INDEX('Cleaned Data'!$I$43:$M$43,MATCH(TRIM($B$48),TRIM('Cleaned Data'!$I$39:$M$39),0)),INDEX('Cleaned Data'!$P$43:$T$43,MATCH(TRIM($B$48),TRIM('Cleaned Data'!$P$39:$T$39),0))))} -> #N/A | D53: =B53*C53 -> #N/A | F53: Production Days | G53: 3 | H53: {=IF($G$49="A List",INDEX('Cleaned Data'!$B$43:$F$43,MATCH(TRIM($G$48),TRIM('Cleaned Data'!$B$39:$F$39),0)),IF($G$49="Supporting",INDEX('Cleaned Data'!$I$43:$M$43,MATCH(TRIM($G$48),TRIM('Cleaned Data'!$I$39:$M$39),0)),INDEX('Cleaned Data'!$P$43:$T$43,MATCH(TRIM($G$48),TRIM('Cleaned Data'!$P$39:$T$39),0))))} -> 250000 | I53: =G53*H53 -> 750000 | K53: Production Days | L53: 1 | M53: {=IF($L$49="A List",INDEX('Cleaned Data'!$B$43:$F$43,MATCH(TRIM($L$48),TRIM('Cleaned Data'!$B$39:$F$39),0)),IF($L$49="Supporting",INDEX('Cleaned Data'!$I$43:$M$43,MATCH(TRIM($L$48),TRIM('Cleaned Data'!$I$39:$M$39),0)),INDEX('Cleaned Data'!$P$43:$T$43,MATCH(TRIM($L$48),TRIM('Cleaned Data'!$P$39:$T$39),0))))} -> 85000 | N53: =L53*M53 -> 85000 | P53: Production Days | Q53: 2 | R53: {=IF($Q$49="A List",INDEX('Cleaned Data'!$B$43:$F$43,MATCH(TRIM($Q$48),TRIM('Cleaned Data'!$B$39:$F$39),0)),IF($Q$49="Supporting",INDEX('Cleaned Data'!$I$43:$M$43,MATCH(TRIM($Q$48),TRIM('Cleaned Data'!$I$39:$M$39),0)),INDEX('Cleaned Data'!$P$43:$T$43,MATCH(TRIM($Q$48),TRIM('Cleaned Data'!$P$39:$T$39),0))))} -> 125000 | S53: =Q53*R53 -> 250000
A54: Social Media Posts | C54: {=IF($B$49="A List",INDEX('Cleaned Data'!$B$45:$F$45,MATCH(TRIM($B$48),TRIM('Cleaned Data'!$B$39:$F$39),0)),IF($B$49="Supporting",INDEX('Cleaned Data'!$I$45:$M$45,MATCH(TRIM($B$48),TRIM('Cleaned Data'!$I$39:$M$39),0)),INDEX('Cleaned Data'!$P$45:$T$45,MATCH(TRIM($B$48),TRIM('Cleaned Data'!$P$39:$T$39),0))))} -> #N/A | D54: =B54*C54 -> #N/A | F54: Social Media Posts | G54: 15 | H54: {=IF($G$49="A List",INDEX('Cleaned Data'!$B$45:$F$45,MATCH(TRIM($G$48),TRIM('Cleaned Data'!$B$39:$F$39),0)),IF($G$49="Supporting",INDEX('Cleaned Data'!$I$45:$M$45,MATCH(TRIM($G$48),TRIM('Cleaned Data'!$I$39:$M$39),0)),INDEX('Cleaned Data'!$P$45:$T$45,MATCH(TRIM($G$48),TRIM('Cleaned Data'!$P$39:$T$39),0))))} -> 80000 | I54: =G54*H54 -> 1200000 | K54: Social Media Posts | L54: 5 | M54: {=IF($L$49="A List",INDEX('Cleaned Data'!$B$45:$F$45,MATCH(TRIM($L$48),TRIM('Cleaned Data'!$B$39:$F$39),0)),IF($L$49="Supporting",INDEX('Cleaned Data'!$I$45:$M$45,MATCH(TRIM($L$48),TRIM('Cleaned Data'!$I$39:$M$39),0)),INDEX('Cleaned Data'!$P$45:$T$45,MATCH(TRIM($L$48),TRIM('Cleaned Data'!$P$39:$T$39),0))))} -> 35000 | N54: =L54*M54 -> 175000 | P54: Social Media Posts | Q54: 3 | R54: {=IF($Q$49="A List",INDEX('Cleaned Data'!$B$45:$F$45,MATCH(TRIM($Q$48),TRIM('Cleaned Data'!$B$39:$F$39),0)),IF($Q$49="Supporting",INDEX('Cleaned Data'!$I$45:$M$45,MATCH(TRIM($Q$48),TRIM('Cleaned Data'!$I$39:$M$39),0)),INDEX('Cleaned Data'!$P$45:$T$45,MATCH(TRIM($Q$48),TRIM('Cleaned Data'!$P$39:$T$39),0))))} -> 35000 | S54: =Q54*R54 -> 105000
A55: Appearances | C55: {=IF($B$49="A List",INDEX('Cleaned Data'!$B$44:$F$44,MATCH(TRIM($B$48),TRIM('Cleaned Data'!$B$39:$F$39),0)),IF($B$49="Supporting",INDEX('Cleaned Data'!$I$44:$M$44,MATCH(TRIM($B$48),TRIM('Cleaned Data'!$I$39:$M$39),0)),INDEX('Cleaned Data'!$P$44:$T$44,MATCH(TRIM($B$48),TRIM('Cleaned Data'!$P$39:$T$39),0))))} -> #N/A | D55: =B55*C55 -> #N/A | F55: Appearances | G55: 1 | H55: {=IF($G$49="A List",INDEX('Cleaned Data'!$B$44:$F$44,MATCH(TRIM($G$48),TRIM('Cleaned Data'!$B$39:$F$39),0)),IF($G$49="Supporting",INDEX('Cleaned Data'!$I$44:$M$44,MATCH(TRIM($G$48),TRIM('Cleaned Data'!$I$39:$M$39),0)),INDEX('Cleaned Data'!$P$44:$T$44,MATCH(TRIM($G$48),TRIM('Cleaned Data'!$P$39:$T$39),0))))} -> 175000 | I55: =G55*H55 -> 175000 | K55: Appearances | L55: 2 | M55: {=IF($L$49="A List",INDEX('Cleaned Data'!$B$44:$F$44,MATCH(TRIM($L$48),TRIM('Cleaned Data'!$B$39:$F$39),0)),IF($L$49="Supporting",INDEX('Cleaned Data'!$I$44:$M$44,MATCH(TRIM($L$48),TRIM('Cleaned Data'!$I$39:$M$39),0)),INDEX('Cleaned Data'!$P$44:$T$44,MATCH(TRIM($L$48),TRIM('Cleaned Data'!$P$39:$T$39),0))))} -> 55000 | N55: =L55*M55 -> 110000 | P55: Appearances | Q55: 0 | R55: {=IF($Q$49="A List",INDEX('Cleaned Data'!$B$44:$F$44,MATCH(TRIM($Q$48),TRIM('Cleaned Data'!$B$39:$F$39),0)),IF($Q$49="Supporting",INDEX('Cleaned Data'!$I$44:$M$44,MATCH(TRIM($Q$48),TRIM('Cleaned Data'!$I$39:$M$39),0)),INDEX('Cleaned Data'!$P$44:$T$44,MATCH(TRIM($Q$48),TRIM('Cleaned Data'!$P$39:$T$39),0))))} -> 50000 | S55: =Q55*R55 -> 0
A56: Tour Sponsorship | C56: {=IF($B$49="A List",INDEX('Cleaned Data'!$B$41:$F$41,MATCH(TRIM($B$48),TRIM('Cleaned Data'!$B$39:$F$39),0)),IF($B$49="Supporting",INDEX('Cleaned Data'!$I$41:$M$41,MATCH(TRIM($B$48),TRIM('Cleaned Data'!$I$39:$M$39),0)),INDEX('Cleaned Data'!$P$41:$T$41,MATCH(TRIM($B$48),TRIM('Cleaned Data'!$P$39:$T$39),0))))} -> #N/A | D56: =B56*C56 -> #N/A | F56: Tour Sponsorship | G56: 1 | H56: {=IF($G$49="A List",INDEX('Cleaned Data'!$B$41:$F$41,MATCH(TRIM($G$48),TRIM('Cleaned Data'!$B$39:$F$39),0)),IF($G$49="Supporting",INDEX('Cleaned Data'!$I$41:$M$41,MATCH(TRIM($G$48),TRIM('Cleaned Data'!$I$39:$M$39),0)),INDEX('Cleaned Data'!$P$41:$T$41,MATCH(TRIM($G$48),TRIM('Cleaned Data'!$P$39:$T$39),0))))} -> 1500000 | I56: =G56*H56 -> 1500000 | K56: Tour Sponsorship | L56: 0 | M56: {=IF($L$49="A List",INDEX('Cleaned Data'!$B$41:$F$41,MATCH(TRIM($L$48),TRIM('Cleaned Data'!$B$39:$F$39),0)),IF($L$49="Supporting",INDEX('Cleaned Data'!$I$41:$M$41,MATCH(TRIM($L$48),TRIM('Cleaned Data'!$I$39:$M$39),0)),INDEX('Cleaned Data'!$P$41:$T$41,MATCH(TRIM($L$48),TRIM('Cleaned Data'!$P$39:$T$39),0))))} -> 0 | N56: =L56*M56 -> 0 | P56: Tour Sponsorship | Q56: 0 | R56: {=IF($Q$49="A List",INDEX('Cleaned Data'!$B$41:$F$41,MATCH(TRIM($Q$48),TRIM('Cleaned Data'!$B$39:$F$39),0)),IF($Q$49="Supporting",INDEX('Cleaned Data'!$I$41:$M$41,MATCH(TRIM($Q$48),TRIM('Cleaned Data'!$I$39:$M$39),0)),INDEX('Cleaned Data'!$P$41:$T$41,MATCH(TRIM($Q$48),TRIM('Cleaned Data'!$P$39:$T$39),0))))} -> 0 | S56: =Q56*R56 -> 0
A57: Live Performances | C57: {=IF($B$49="A List",INDEX('Cleaned Data'!$B$42:$F$42,MATCH(TRIM($B$48),TRIM('Cleaned Data'!$B$39:$F$39),0)),IF($B$49="Supporting",INDEX('Cleaned Data'!$I$42:$M$42,MATCH(TRIM($B$48),TRIM('Cleaned Data'!$I$39:$M$39),0)),INDEX('Cleaned Data'!$P$42:$T$42,MATCH(TRIM($B$48),TRIM('Cleaned Data'!$P$39:$T$39),0))))} -> #N/A | D57: =B57*C57 -> #N/A | F57: Live Performances | G57: 2 | H57: {=IF($G$49="A List",INDEX('Cleaned Data'!$B$42:$F$42,MATCH(TRIM($G$48),TRIM('Cleaned Data'!$B$39:$F$39),0)),IF($G$49="Supporting",INDEX('Cleaned Data'!$I$42:$M$42,MATCH(TRIM($G$48),TRIM('Cleaned Data'!$I$39:$M$39),0)),INDEX('Cleaned Data'!$P$42:$T$42,MATCH(TRIM($G$48),TRIM('Cleaned Data'!$P$39:$T$39),0))))} -> 1000000 | I57: =G57*H57 -> 2000000 | K57: Live Performances | L57: 0 | M57: {=IF($L$49="A List",INDEX('Cleaned Data'!$B$42:$F$42,MATCH(TRIM($L$48),TRIM('Cleaned Data'!$B$39:$F$39),0)),IF($L$49="Supporting",INDEX('Cleaned Data'!$I$42:$M$42,MATCH(TRIM($L$48),TRIM('Cleaned Data'!$I$39:$M$39),0)),INDEX('Cleaned Data'!$P$42:$T$42,MATCH(TRIM($L$48),TRIM('Cleaned Data'!$P$39:$T$39),0))))} -> 0 | N57: =L57*M57 -> 0 | P57: Live Performances | Q57: 0 | R57: {=IF($Q$49="A List",INDEX('Cleaned Data'!$B$42:$F$42,MATCH(TRIM($Q$48),TRIM('Cleaned Data'!$B$39:$F$39),0)),IF($Q$49="Supporting",INDEX('Cleaned Data'!$I$42:$M$42,MATCH(TRIM($Q$48),TRIM('Cleaned Data'!$I$39:$M$39),0)),INDEX('Cleaned Data'!$P$42:$T$42,MATCH(TRIM($Q$48),TRIM('Cleaned Data'!$P$39:$T$39),0))))} -> 0 | S57: =Q57*R57 -> 0
A58: Tickets | C58: {=IF($B$49="A List",INDEX('Cleaned Data'!$B$46:$F$46,MATCH(TRIM($B$48),TRIM('Cleaned Data'!$B$39:$F$39),0)),IF($B$49="Supporting",INDEX('Cleaned Data'!$I$46:$M$46,MATCH(TRIM($B$48),TRIM('Cleaned Data'!$I$39:$M$39),0)),INDEX('Cleaned Data'!$P$46:$T$46,MATCH(TRIM($B$48),TRIM('Cleaned Data'!$P$39:$T$39),0))))} -> #N/A | D58: =B58*C58 -> #N/A | F58: Tickets | G58: 200 | H58: {=IF($G$49="A List",INDEX('Cleaned Data'!$B$46:$F$46,MATCH(TRIM($G$48),TRIM('Cleaned Data'!$B$39:$F$39),0)),IF($G$49="Supporting",INDEX('Cleaned Data'!$I$46:$M$46,MATCH(TRIM($G$48),TRIM('Cleaned Data'!$I$39:$M$39),0)),INDEX('Cleaned Data'!$P$46:$T$46,MATCH(TRIM($G$48),TRIM('Cleaned Data'!$P$39:$T$39),0))))} -> 300 | I58: =G58*H58 -> 60000 | K58: Tickets | L58: 0 | M58: {=IF($L$49="A List",INDEX('Cleaned Data'!$B$46:$F$46,MATCH(TRIM($L$48),TRIM('Cleaned Data'!$B$39:$F$39),0)),IF($L$49="Supporting",INDEX('Cleaned Data'!$I$46:$M$46,MATCH(TRIM($L$48),TRIM('Cleaned Data'!$I$39:$M$39),0)),INDEX('Cleaned Data'!$P$46:$T$46,MATCH(TRIM($L$48),TRIM('Cleaned Data'!$P$39:$T$39),0))))} -> 150 | N58: =L58*M58 -> 0 | P58: Tickets | Q58: 0 | R58: {=IF($Q$49="A List",INDEX('Cleaned Data'!$B$46:$F$46,MATCH(TRIM($Q$48),TRIM('Cleaned Data'!$B$39:$F$39),0)),IF($Q$49="Supporting",INDEX('Cleaned Data'!$I$46:$M$46,MATCH(TRIM($Q$48),TRIM('Cleaned Data'!$I$39:$M$39),0)),INDEX('Cleaned Data'!$P$46:$T$46,MATCH(TRIM($Q$48),TRIM('Cleaned Data'!$P$39:$T$39),0))))} -> 0 | S58: =Q58*R58 -> 0
A59: Line-Item Total | D59: =SUM(D52:D58) -> #N/A | F59: Line-Item Total | I59: =SUM(I52:I58) -> 8185000 | K59: Line-Item Total | N59: =SUM(N52:N58) -> 370000 | P59: Line-Item Total | S59: =SUM(S52:S58) -> 355000
...
